Workbook

Sheet 재료사전
A1: 표기 원문 | B1: 표준명 | C1: 카테고리 | D1: 대체가능군 | E1: 유형 | F1: 비고
A2: 고춧가루 | B2: 고춧가루 | C2: 양념 | D2: - | E2: 정상
A3: 고추가루 | B3: 고춧가루 | C3: 양념 | D3: - | E3: 오탈자 | F3: 맞춤법 오류
A4: 고추가룻 | B4: 고춧가루 | C4: 양념 | D4: - | E4: 오탈자 | F4: 오타
A5: 다진마늘 | B5: 다진마늘 | C5: 양념 | D5: 마늘 | E5: 정상
A6: 다진 마늘 | B6: 다진마늘 | C6: 양념 | D6: 마늘 | E6: 띄어쓰기 | F6: 공백 차이
A7: 간장 | B7: 진간장 | C7: 양념 | D7: - | E7: 모호 | F7: 어떤 간장인지 불명 - 확인 필요
A8: 진간장 | B8: 진간장 | C8: 양념 | D8: - | E8: 정상
A9: 국간장 | B9: 국간장 | C9: 양념 | D9: - | E9: 정상 | F9: 진간장과 대체 불가
A10: 된장 | B10: 된장 | C10: 양념 | D10: - | E10: 정상
A11: 토장 | B11: 된장 | C11: 양념 | D11: - | E11: 별칭 | F11: 본문에 토장(된장)으로 병기
A12: 액젓 | B12: 멸치액젓 | C12: 양념 | D12: 까나리액젓 | E12: 상위어 | F12: 종류 미지정
A13: 멸치액젓 | B13: 멸치액젓 | C13: 양념 | D13: 까나리액젓 | E13: 정상
A14: 참치액 | B14: 참치액 | C14: 양념 | D14: - | E14: 정상
A15: 맛소금 | B15: 소금 | C15: 양념 | D15: - | E15: 별칭
A16: 깨소금 | B16: 깨 | C16: 양념 | D16: - | E16: 정상
A17: 설탕 | B17: 설탕 | C17: 양념 | D17: 올리고당/알룰로스 | E17: 정상
A18: 올리고당 | B18: 올리고당 | C18: 양념 | D18: 설탕/알룰로스 | E18: 정상
A19: 알룰로스 | B19: 알룰로스 | C19: 양념 | D19: 설탕/올리고당 | E19: 정상
A20: 굴소스 | B20: 굴소스 | C20: 양념 | D20: - | E20: 정상
A21: 고추장 | B21: 고추장 | C21: 양념 | D21: - | E21: 정상
A22: 식초 | B22: 식초 | C22: 양념 | D22: - | E22: 정상
A23: 맛술 | B23: 맛술 | C23: 양념 | D23: - | E23: 정상
A24: 참기름 | B24: 참기름 | C24: 양념 | D24: - | E24: 정상
... A26: 후추 | B26: 후추 | C26: 양념 | D26: - | E26: 정상
A27: 삼겹살 | B27: 삼겹살 | C27: 육류 | D27: 돼지고기 | E27: 하위어 | F27: 돼지고기의 부위
A28: 항정살 | B28: 항정살 | C28: 육류 | D28: 돼지고기 | E28: 하위어 | F28: 돼지고기의 부위
A29: 돼지고기 | B29: 돼지고기 | C29: 육류 | D29: - | E29: 상위어 | F29: 부위 미지정
A30: 부채살 | B30: 부채살 | C30: 육류 | D30: 소고기 | E30: 하위어 | F30: 본문에서는 소고기로 지칭 - 불일치
A31: 우삼겹 | B31: 우삼겹 | C31: 육류 | D31: 소고기 | E31: 하위어 | F31: 소고기의 부위
A32: 소고기 | B32: 소고기 | C32: 육류 | D32: - | E32: 상위어 | F32: 부위 미지정
A33: 닭다리 | B33: 닭 | C33: 육류 | D33: 닭 | E33: 하위어 | F33: DB속성은 닭, 본문은 닭다리 - 불일치
A34: 리챔 | B34: 런천미트 | C34: 가공식품 | D34: 스팸 | E34: 브랜드명 | F34: DB속성은 스팸, 본문은 리챔 - 불일치
A35: 스팸 | B35: 런천미트 | C35: 가공식품 | D35: 리챔 | E35: 브랜드명
A36: 대파 | B36: 대파 | C36: 채소 | D36: - | E36: 정상 | F36: 쪽파/실파와 구분 필요
A37: 양파 | B37: 양파 | C37: 채소 | D37: - | E37: 정상
A38: 애호박 | B38: 애호박 | C38: 채소 | D38: - | E38: 정상
A39: 감자 | B39: 감자 | C39: 채소 | D39: - | E39: 정상
A40: 무 | B40: 무 | C40: 채소 | D40: - | E40: 정상 | F40: 1글자 - 문자열 매칭 시 오탐 위험
A41: 청양고추 | B41: 청양고추 | C41: 채소 | D41: - | E41: 정상
...

Sheet 단위표기
A1: 표기 원문 | B1: 해석 | C1: 표준화 | D1: 비고
A2: 1 / 2 / 3 (단위 없음) | B2: 큰술로 추정 | C2: tbsp | D2: 가장 흔한 표기 - 추정 필요
A3: 1T / 3T | B3: 큰술 | C3: tbsp | D3: 같은 레시피 안에서 숫자만 표기와 혼용됨
A4: 1큰술 | B4: 큰술 | C4: tbsp
A5: 1스푼 | B5: 큰술로 추정 | C5: tbsp | D5: 큰술과 동일한지 불확실
A6: 3꼬집 | B6: 꼬집 | C6: pinch | D6: 계량 불가 - 정성 단위
A7: 적당히 / 적당량 / 약간 / 넉넉히 | B7: 정량 없음 | C7: N/A | D7: 소비량 계산 불가
A8: 400ml / 300ml / 700 | B8: 부피 | C8: ml | D8: 700은 단위 누락
A9: 240g / 150g / 500g | B9: 중량 | C9: g
A10: 2알 / 1/2개 / 1대 | B10: 개수 | C10: ea | D10: 재료마다 단위가 다름
A11: 1/2 / 1/3 | B11: 분수 개수 | C11: ea | D11: 기준 크기 불명

Sheet 요약
A1: 1단계: 재료 정규화 분석 결과
A3: 항목 | B3: 값 | C3: 출처
A4: 노션 DB 총 레시피 수 | B4: 33 | C4: 입력값 - Notion DB 조회 결과
A5: 본문 확인한 샘플 수 | B5: 9 | C5: 입력값
A6: └ 재료가 텍스트로 있음 | B6: 5 | C6: 입력값
A7: └ 재료가 이미지에만 있음 | B7: 3 | C7: 입력값
A8: └ 일부만 텍스트 | B8: 1 | C8: 입력값
A9: 이미지 의존 비율 | B9: =(B7+B8)/B5 -> 0.44444444 | C9: 텍스트 파싱만으로는 재료를 못 얻는 비율
A10: 33건 환산 시 이미지 의존 건수 | B10: =ROUND(B4*B9,0) -> 15 | C10: 샘플 비율을 전체에 적용한 추정치
A12: 사전 등록 표기 수 | B12: =COUNTA(재료사전!A2:A100) -> 47
A13: 표준명 종류 수 | B13: 40 | C13: 중복 제거 후 실제 재료 종류 (Python 집계)
A14: └ 오탈자/띄어쓰기 변형 | B14: =COUNTIF(재료사전!E2:E100,"오탈자")+COUNTIF(재료사전!E2:E100,"띄어쓰기") -> 3
A15: └ 별칭·브랜드명 | B15: =COUNTIF(재료사전!E2:E100,"별칭")+COUNTIF(재료사전!E2:E100,"브랜드명") -> 4
A16: └ 상위어/하위어 (부위·종류) | B16: =COUNTIF(재료사전!E2:E100,"상위어")+COUNTIF(재료사전!E2:E100,"하위어") -> 8
A17: └ 모호 (판정 불가) | B17: =COUNTIF(재료사전!E2:E100,"모호") -> 1
A18: 정규화 손봐야 하는 표기 비율 | B18: =(B14+B15+B16+B17)/B12 -> 0.34042553
A20: ※ 파란 글씨 = 실측/입력값, 검정 = 수식

Sheet AI원가
A1: 2단계: AI 레시피 구조화 건당 원가
A3: 가정값
A4: 시스템 프롬프트 토큰 | B4: 600 | D4: 스키마+few-shot 포함 추정
A5: 출력 토큰 | B5: 700 | D5: 구조화 JSON 결과 추정
A6: 텍스트 레시피 평균 토큰 | B6: 289 | D6: 실측: 노션 레시피 3건 평균 289자
A7: 캡처 이미지 1장 토큰 | B7: 1515 | D7: (725x1568)/750, Anthropic 산식
A8: 환율 (원/USD) | B8: 1380 | D8: 가정값
A10: 모델 단가 (USD / 백만 토큰)
A11: 모델 | B11: 입력 | C11: 출력
A12: Haiku 4.5 | B12: 1 | C12: 5
A13: Sonnet 5 | B13: 2 | C13: 10
A14: Opus 5 | B14: 5 | C14: 25
A15: ※ Sonnet 5는 2026-08-31까지 도입가 $2/$10, 이후 $3/$15
A17: 건당 원가 (원)
A18: 시나리오 | B18: Haiku 4.5 | C18: Sonnet 5 | D18: Opus 5
A19: A. 텍스트 붙여넣기 | B19: =(($B$4+$B$6)/1000000*$B$12+$B$5/1000000*$C$12)*$B$8 -> 6.05682 | C19: =(($B$4+$B$6)/1000000*$B$13+$B$5/1000000*$C$13)*$B$8 -> 12.11364 | D19: =(($B$4+$B$6)/1000000*$B$14+$B$5/1000000*$C$14)*$B$8 -> 30.2841
A20: B. 캡처 1장 | B20: =(($B$4+$B$7)/1000000*$B$12+$B$5/1000000*$C$12)*$B$8 -> 7.7487 | C20: =(($B$4+$B$7)/1000000*$B$13+$B$5/1000000*$C$13)*$B$8 -> 15.4974 | D20: =(($B$4+$B$7)/1000000*$B$14+$B$5/1000000*$C$14)*$B$8 -> 38.7435
A21: C. 캡처 3장 | B21: =(($B$4+$B$7*3)/1000000*$B$12+$B$5/1000000*$C$12)*$B$8 -> 11.9301 | C21: =(($B$4+$B$7*3)/1000000*$B$13+$B$5/1000000*$C$13)*$B$8 -> 23.8602 | D21: =(($B$4+$B$7*3)/1000000*$B$14+$B$5/1000000*$C$14)*$B$8 -> 59.6505
A23: 월 1,000건 처리 시 (원)
A24: 시나리오 | B24: Haiku 4.5 | C24: Sonnet 5 | D24: Opus 5
A25: A. 텍스트 붙여넣기 | B25: =B19*1000 -> 6056.82 | C25: =C19*1000 -> 12113.64 | D25: =D19*1000 -> 30284.1
A26: B. 캡처 1장 | B26: =B20*1000 -> 7748.7 | C26: =C20*1000 -> 15497.4 | D26: =D20*1000 -> 38743.5
A27: C. 캡처 3장 | B27: =B21*1000 -> 11930.1 | C27: =C21*1000 -> 23860.2 | D27: =D21*1000 -> 59650.5
